<?xml version="1.0"?>
<robot name="diff_drive_robot" xmlns:xacro="http://www.ros.org/wiki/xacro">

  <!-- ===== Properties ===== -->
  <xacro:property name="base_length"  value="0.40"/>
  <xacro:property name="base_width"   value="0.30"/>
  <xacro:property name="base_height"  value="0.15"/>
  <xacro:property name="wheel_radius" value="0.06"/>
  <xacro:property name="wheel_width"  value="0.04"/>
  <xacro:property name="wheel_offset_y" value="0.175"/>
  <xacro:property name="caster_radius" value="0.03"/>

  <!-- ===== Materials ===== -->
  <material name="blue">  <color rgba="0.0 0.0 0.8 1.0"/> </material>
  <material name="black"> <color rgba="0.0 0.0 0.0 1.0"/> </material>
  <material name="grey">  <color rgba="0.5 0.5 0.5 1.0"/> </material>
  <material name="red">   <color rgba="0.8 0.0 0.0 1.0"/> </material>

  <!-- ===== Base footprint (root) ===== -->
  <link name="base_footprint"/>

  <joint name="base_footprint_joint" type="fixed">
    <parent link="base_footprint"/>
    <child  link="base_link"/>
    <origin xyz="0 0 ${wheel_radius}" rpy="0 0 0"/>
  </joint>

  <!-- ===== Base link ===== -->
  <link name="base_link">
    <visual>
      <geometry>
        <box size="${base_length} ${base_width} ${base_height}"/>
      </geometry>
      <material name="blue"/>
    </visual>
    <collision>
      <geometry>
        <box size="${base_length} ${base_width} ${base_height}"/>
      </geometry>
    </collision>
    <inertial>
      <mass value="5.0"/>
      <inertia ixx="0.0395" ixy="0.0" ixz="0.0"
               iyy="0.0682" iyz="0.0"
               izz="0.0977"/>
    </inertial>
  </link>

  <!-- ===== Left wheel ===== -->
  <link name="left_wheel">
    <visual>
      <geometry>
        <cylinder radius="${wheel_radius}" length="${wheel_width}"/>
      </geometry>
      <material name="black"/>
    </visual>
    <collision>
      <geometry>
        <cylinder radius="${wheel_radius}" length="${wheel_width}"/>
      </geometry>
    </collision>
    <inertial>
      <mass value="0.5"/>
      <inertia ixx="0.000526" ixy="0.0" ixz="0.0"
               iyy="0.000526" iyz="0.0"
               izz="0.0009"/>
    </inertial>
  </link>

  <joint name="left_wheel_joint" type="continuous">
    <parent link="base_link"/>
    <child  link="left_wheel"/>
    <origin xyz="0 ${wheel_offset_y} 0" rpy="-1.5708 0 0"/>
    <axis xyz="0 0 1"/>
  </joint>

  <!-- ===== Right wheel ===== -->
  <link name="right_wheel">
    <visual>
      <geometry>
        <cylinder radius="${wheel_radius}" length="${wheel_width}"/>
      </geometry>
      <material name="black"/>
    </visual>
    <collision>
      <geometry>
        <cylinder radius="${wheel_radius}" length="${wheel_width}"/>
      </geometry>
    </collision>
    <inertial>
      <mass value="0.5"/>
      <inertia ixx="0.000526" ixy="0.0" ixz="0.0"
               iyy="0.000526" iyz="0.0"
               izz="0.0009"/>
    </inertial>
  </link>

  <joint name="right_wheel_joint" type="continuous">
    <parent link="base_link"/>
    <child  link="right_wheel"/>
    <origin xyz="0 -${wheel_offset_y} 0" rpy="-1.5708 0 0"/>
    <axis xyz="0 0 1"/>
  </joint>

  <!-- ===== Front caster ===== -->
  <link name="caster_front">
    <visual>
      <geometry><sphere radius="${caster_radius}"/></geometry>
      <material name="grey"/>
    </visual>
    <collision>
      <geometry><sphere radius="${caster_radius}"/></geometry>
    </collision>
    <inertial>
      <mass value="0.1"/>
      <inertia ixx="0.000036" ixy="0.0" ixz="0.0"
               iyy="0.000036" iyz="0.0"
               izz="0.000036"/>
    </inertial>
  </link>

  <joint name="caster_front_joint" type="fixed">
    <parent link="base_link"/>
    <child  link="caster_front"/>
    <origin xyz="${base_length/2 - caster_radius} 0 ${-base_height/2}" rpy="0 0 0"/>
  </joint>

  <!-- ===== Rear caster ===== -->
  <link name="caster_rear">
    <visual>
      <geometry><sphere radius="${caster_radius}"/></geometry>
      <material name="grey"/>
    </visual>
    <collision>
      <geometry><sphere radius="${caster_radius}"/></geometry>
    </collision>
    <inertial>
      <mass value="0.1"/>
      <inertia ixx="0.000036" ixy="0.0" ixz="0.0"
               iyy="0.000036" iyz="0.0"
               izz="0.000036"/>
    </inertial>
  </link>

  <joint name="caster_rear_joint" type="fixed">
    <parent link="base_link"/>
    <child  link="caster_rear"/>
    <origin xyz="${-(base_length/2 - caster_radius)} 0 ${-base_height/2}" rpy="0 0 0"/>
  </joint>

  <!-- ===== IMU link ===== -->
  <link name="imu_link">
    <visual>
      <geometry><box size="0.04 0.04 0.02"/></geometry>
      <material name="red"/>
    </visual>
    <inertial>
      <mass value="0.01"/>
      <inertia ixx="0.0" ixy="0.0" ixz="0.0"
               iyy="0.0" iyz="0.0" izz="0.0"/>
    </inertial>
  </link>

  <joint name="imu_joint" type="fixed">
    <parent link="base_link"/>
    <child  link="imu_link"/>
    <origin xyz="0 0 ${base_height/2}" rpy="0 0 0"/>
  </joint>

  <!-- ===== LIDAR link ===== -->
  <link name="lidar_link">
    <visual>
      <geometry><cylinder radius="0.04" length="0.06"/></geometry>
      <material name="grey"/>
    </visual>
    <collision>
      <geometry><cylinder radius="0.04" length="0.06"/></geometry>
    </collision>
    <inertial>
      <mass value="0.1"/>
      <inertia ixx="0.000043" ixy="0.0" ixz="0.0"
               iyy="0.000043" iyz="0.0"
               izz="0.00008"/>
    </inertial>
  </link>

  <joint name="lidar_joint" type="fixed">
    <parent link="base_link"/>
    <child  link="lidar_link"/>
    <origin xyz="0 0 ${base_height/2 + 0.05}" rpy="0 0 0"/>
  </joint>

  <!-- ===== Gazebo plugins ===== -->

  <!-- Differential drive controller -->
  <gazebo>
    <plugin name="diff_drive_controller" filename="libgazebo_ros_diff_drive.so">
      <ros>
        <namespace>/</namespace>
      </ros>
      <left_joint>left_wheel_joint</left_joint>
      <right_joint>right_wheel_joint</right_joint>
      <wheel_separation>${wheel_offset_y * 2}</wheel_separation>
      <wheel_diameter>${wheel_radius * 2}</wheel_diameter>
      <max_wheel_torque>20</max_wheel_torque>
      <max_wheel_acceleration>1.0</max_wheel_acceleration>
      <command_topic>cmd_vel</command_topic>
      <publish_odom>true</publish_odom>
      <publish_odom_tf>true</publish_odom_tf>
      <publish_wheel_tf>true</publish_wheel_tf>
      <odometry_topic>odom</odometry_topic>
      <odometry_frame>odom</odometry_frame>
      <!-- base_link is the Nav2 convention; odom→base_link TF is published here -->
      <robot_base_frame>base_link</robot_base_frame>
    </plugin>
  </gazebo>

  <!-- IMU sensor plugin -->
  <gazebo reference="imu_link">
    <sensor name="imu_sensor" type="imu">
      <always_on>true</always_on>
      <update_rate>50</update_rate>
      <visualize>true</visualize>
      <plugin filename="libgazebo_ros_imu_sensor.so" name="imu_plugin">
        <ros>
          <namespace>/</namespace>
          <remapping>~/out:=imu</remapping>
        </ros>
        <initial_orientation_as_reference>false</initial_orientation_as_reference>
      </plugin>
    </sensor>
  </gazebo>

  <!-- LIDAR sensor plugin -->
  <gazebo reference="lidar_link">
    <sensor name="lidar_sensor" type="ray">
      <always_on>true</always_on>
      <visualize>true</visualize>
      <update_rate>10</update_rate>
      <ray>
        <scan>
          <horizontal>
            <samples>360</samples>
            <resolution>1</resolution>
            <min_angle>-3.14159</min_angle>
            <max_angle>3.14159</max_angle>
          </horizontal>
        </scan>
        <range>
          <min>0.12</min>
          <max>10.0</max>
          <resolution>0.01</resolution>
        </range>
        <noise>
          <type>gaussian</type>
          <mean>0.0</mean>
          <stddev>0.01</stddev>
        </noise>
      </ray>
      <plugin filename="libgazebo_ros_ray_sensor.so" name="lidar_plugin">
        <ros>
          <namespace>/</namespace>
          <remapping>~/out:=scan</remapping>
        </ros>
        <output_type>sensor_msgs/LaserScan</output_type>
        <frame_name>lidar_link</frame_name>
      </plugin>
    </sensor>
  </gazebo>

  <!-- Base link colour in Gazebo -->
  <gazebo reference="base_link">
    <material>Gazebo/Blue</material>
  </gazebo>
  <gazebo reference="left_wheel">
    <material>Gazebo/Black</material>
  </gazebo>
  <gazebo reference="right_wheel">
    <material>Gazebo/Black</material>
  </gazebo>

</robot>
